Workbook

Sheet Sheet1
A1: 成品当日发货清单
A2: 工厂地址：四川省达州市渠县经济开发区 | G2: 制单人：代艳 | I2: 联系电话1368664967 | K2: 备注：装车时按从上下到的顺序装车 | Q2: CARTON DIMENSIONS | T2: CRTN CBM (M3) | U2: TOTAL CBM (M3)
A3: 发车日期 | B3: 客户 | C3: 生产单号 | D3: 销售单号 | E3: PO.NO | F3: 款号 | G3: 产品名称 | H3: 总箱数 | I3: 实发数量 | J3: 单位 | K3: 产地 | L3: 件数 | M3: CBM | N3: 是否验货 | O3: 备注 | P3: 运输方式 | Q3: L (cm) | R3: W (cm) | S3: H (cm)
A4: 46028 | B4: Amazon US | C4: POHK-25-20307 | E4: 56WW9AFR/62V4ESGH/8SDSE5WZ | F4: 12369（3） | G4: 成品 | I4: =+L4*3 -> 765 | J4: 个 | K4: 装配 | L4: 255 | M4: =+U4 -> 19.28314 | N4: 已 | P4: 车牌:川S86094 挂车：川S8451挂 车型：17.5x3x3厢车 5轴160 司机，谢营海 电话：18381906318 | Q4: =VLOOKUP($F4,[1]装箱单!$A:$E,5,0) -> 48.26 | R4: =VLOOKUP($F4,[1]装箱单!$A:$F,6,0) -> 36.83 | S4: =VLOOKUP($F4,[1]装箱单!$A:$G,7,0) -> 42.545 | T4: =VLOOKUP($F4,[1]装箱单!$A:$J,10,0) -> 0.075620155 | U4: =+T4*L4 -> 19.28314
A5: 46028 | B5: Amazon US | C5: POHK-25-20307 | E5: 7783ULHC/5CN6AL7T | F5: 14747(12) | G5: 成品 | I5: =+L5*12 -> 324 | J5: 个 | K5: 装配 | L5: 27 | M5: =+U5 -> 2.8152408 | N5: 已 | Q5: =VLOOKUP($F5,[1]装箱单!$A:$E,5,0) -> 60.96 | R5: =VLOOKUP($F5,[1]装箱单!$A:$F,6,0) -> 51.8 | S5: =VLOOKUP($F5,[1]装箱单!$A:$G,7,0) -> 33.02 | T5: =VLOOKUP($F5,[1]装箱单!$A:$J,10,0) -> 0.10426818 | U5: =+T5*L5 -> 2.8152408
A6: 46028 | B6: WM（Modset） | C6: POHK-25-19078 | E6: 954188898 | F6: 28483 | G6: 成品 | I6: 1542 | J6: 个 | K6: 装配 | L6: 1542 | M6: =+U6 -> 8.901488 | N6: 已 | Q6: =VLOOKUP($F6,[1]装箱单!$A:$E,5,0) -> 16.83 | R6: =VLOOKUP($F6,[1]装箱单!$A:$F,6,0) -> 17.15 | S6: =VLOOKUP($F6,[1]装箱单!$A:$G,7,0) -> 20 | T6: =VLOOKUP($F6,[1]装箱单!$A:$J,10,0) -> 0.00577269 | U6: =+T6*L6 -> 8.901488
A7: 46028 | B7: WM US | C7: POHK-25-19227 | E7: 954188464 | F7: 28483 | G7: 成品 | I7: 1800 | J7: 个 | K7: 装配 | L7: 1800 | M7: =+U7 -> 10.390842 | N7: 已 | Q7: =VLOOKUP($F7,[1]装箱单!$A:$E,5,0) -> 16.83 | R7: =VLOOKUP($F7,[1]装箱单!$A:$F,6,0) -> 17.15 | S7: =VLOOKUP($F7,[1]装箱单!$A:$G,7,0) -> 20 | T7: =VLOOKUP($F7,[1]装箱单!$A:$J,10,0) -> 0.00577269 | U7: =+T7*L7 -> 10.390842
A8: 46028 | B8: WM US | C8: POHK-25-19228 | E8: 954188459 | F8: 28483 | G8: 成品 | I8: 1800 | J8: 个 | K8: 装配 | L8: 1800 | M8: =+U8 -> 10.390842 | N8: 已 | Q8: =VLOOKUP($F8,[1]装箱单!$A:$E,5,0) -> 16.83 | R8: =VLOOKUP($F8,[1]装箱单!$A:$F,6,0) -> 17.15 | S8: =VLOOKUP($F8,[1]装箱单!$A:$G,7,0) -> 20 | T8: =VLOOKUP($F8,[1]装箱单!$A:$J,10,0) -> 0.00577269 | U8: =+T8*L8 -> 10.390842
A9: 46028 | B9: PT Emway | C9: POHK-25-17959 | E9: 25000352 | F9: 33475（18） | G9: 成品 | I9: 152766 | J9: 个 | K9: 装配 | L9: 8487 | M9: =+U9 -> 49.165298 | N9: 已 | Q9: =VLOOKUP($F9,[1]装箱单!$A:$E,5,0) -> 32.385 | R9: =VLOOKUP($F9,[1]装箱单!$A:$F,6,0) -> 18.78 | S9: =VLOOKUP($F9,[1]装箱单!$A:$G,7,0) -> 9.525 | T9: =VLOOKUP($F9,[1]装箱单!$A:$J,10,0) -> 0.0057930126 | U9: =+T9*L9 -> 49.165298
A10: 46028 | B10: WM（Modset） | C10: POHK-25-19085 | E10: 954188907 | F10: 28481 | G10: 成品 | I10: =+L10*4 -> 2388 | J10: 套 | K10: 装配 | L10: 597 | M10: =+U10 -> 6.0176217 | N10: 已 | Q10: =VLOOKUP($F10,[1]装箱单!$A:$E,5,0) -> 23.81 | R10: =VLOOKUP($F10,[1]装箱单!$A:$F,6,0) -> 17.78 | S10: =VLOOKUP($F10,[1]装箱单!$A:$G,7,0) -> 23.81 | T10: =VLOOKUP($F10,[1]装箱单!$A:$J,10,0) -> 0.010079768 | U10: =+T10*L10 -> 6.0176217
A11: 46028 | B11: WM US | C11: POHK-25-19227 | E11: 954188464 | F11: 28481 | G11: 成品 | I11: =+L11*4 -> 1440 | J11: 套 | K11: 装配 | L11: 360 | M11: =+U11 -> 3.6287166 | N11: 已 | Q11: =VLOOKUP($F11,[1]装箱单!$A:$E,5,0) -> 23.81 | R11: =VLOOKUP($F11,[1]装箱单!$A:$F,6,0) -> 17.78 | S11: =VLOOKUP($F11,[1]装箱单!$A:$G,7,0) -> 23.81 | T11: =VLOOKUP($F11,[1]装箱单!$A:$J,10,0) -> 0.010079768 | U11: =+T11*L11 -> 3.6287166
A12: 46028 | B12: WM US | C12: POHK-25-19228 | E12: 954188459 | F12: 28481 | G12: 成品 | I12: =+L12*4 -> 1440 | J12: 套 | K12: 装配 | L12: 360 | M12: =+U12 -> 3.6287166 | N12: 已 | Q12: =VLOOKUP($F12,[1]装箱单!$A:$E,5,0) -> 23.81 | R12: =VLOOKUP($F12,[1]装箱单!$A:$F,6,0) -> 17.78 | S12: =VLOOKUP($F12,[1]装箱单!$A:$G,7,0) -> 23.81 | T12: =VLOOKUP($F12,[1]装箱单!$A:$J,10,0) -> 0.010079768 | U12: =+T12*L12 -> 3.6287166
A13: 46028 | B13: TJX | C13: POHK-25-21146 | E13: 01-721830/04-721830 06-721830/07-721830 08-721830 | F13: 33454(48) | G13: 成品 | I13: 31824 | J13: 个 | K13: 装配 | L13: 12 | M13: =+U13 -> 0.49047808 | N13: 已 | Q13: =VLOOKUP($F13,[1]装箱单!$A:$E,5,0) -> 37.15 | R13: =VLOOKUP($F13,[1]装箱单!$A:$F,6,0) -> 33 | S13: =VLOOKUP($F13,[1]装箱单!$A:$G,7,0) -> 33.34 | T13: =VLOOKUP($F13,[1]装箱单!$A:$J,10,0) -> 0.040873173 | U13: =+T13*L13 -> 0.49047808
M14: =SUM(M4:M13) -> 114.71238
A15: 46029 | B15: Domestic | C15: 43384 | F15: 320916 | G15: 成品 | I15: =+L15*2 -> 3000 | J15: 个 | K15: 装配 | L15: 1500 | M15: =+U15 -> 38.714439 | N15: 已 | P15: 车牌：川S86004 挂号：川S7549挂 姓名：田道川 电话：13882811838 | Q15: =VLOOKUP($F15,[1]装箱单!$A:$E,5,0) -> 38.1 | R15: =VLOOKUP($F15,[1]装箱单!$A:$F,6,0) -> 30.48 | S15: =VLOOKUP($F15,[1]装箱单!$A:$G,7,0) -> 22.225 | T15: =VLOOKUP($F15,[1]装箱单!$A:$J,10,0) -> 0.025809626 | U15: =+T15*L15 -> 38.714439
A16: 46029 | B16: Domestic | C16: 43721 | F16: 470194 | G16: 成品 | I16: =+L16*2 -> 3000 | J16: 个 | K16: 装配 | L16: 1500 | M16: =+U16 -> 60.836975 | N16: 已 | Q16: =VLOOKUP($F16,[1]装箱单!$A:$E,5,0) -> 41.91 | R16: =VLOOKUP($F16,[1]装箱单!$A:$F,6,0) -> 31.75 | S16: =VLOOKUP($F16,[1]装箱单!$A:$G,7,0) -> 30.48 | T16: =VLOOKUP($F16,[1]装箱单!$A:$J,10,0) -> 0.040557983 | U16: =+T16*L16 -> 60.836975
A17: 46029 | B17: Domestic | C17: 43730 | F17: 320398 | G17: 成品 | I17: =+L17*4 -> 8000 | J17: 套 | K17: 装配 | L17: 2000 | M17: =+U17 -> 20.58 | N17: 已 | Q17: =VLOOKUP($F17,[1]装箱单!$A:$E,5,0) -> 24.5 | R17: =VLOOKUP($F17,[1]装箱单!$A:$F,6,0) -> 21 | S17: =VLOOKUP($F17,[1]装箱单!$A:$G,7,0) -> 20 | T17: =VLOOKUP($F17,[1]装箱单!$A:$J,10,0) -> 0.01029 | U17: =+T17*L17 -> 20.58
A18: 46029 | B18: Domestic | C18: 43721 | F18: 320635 | G18: 成品 | I18: =+L18*2 -> 2596 | J18: 个 | K18: 装配 | L18: =1500-202 -> 1298 | M18: =+U18 -> 20.491184 | N18: 已 | Q18: =VLOOKUP($F18,[1]装箱单!$A:$E,5,0) -> 35.18 | R18: =VLOOKUP($F18,[1]装箱单!$A:$F,6,0) -> 27.18 | S18: =VLOOKUP($F18,[1]装箱单!$A:$G,7,0) -> 16.51 | T18: =VLOOKUP($F18,[1]装箱单!$A:$J,10,0) -> 0.015786737 | U18: =+T18*L18 -> 20.491184
M19: =SUM(M15:M18) -> 140.6226
A20: 46029 | B20: WMUS | C20: POHK-25-18802 | E20: 953742268 | F20: 11369（1） | G20: 成品 | I20: 1122 | J20: 个 | K20: 装配 | L20: 1122 | M20: =+U20 -> 18.199328 | N20: 未 | P20: 车牌：川S80435 电话：18080698059 副驾：王果 电话：18381811233 | Q20: =VLOOKUP($F20,[1]装箱单!$A:$E,5,0) -> 26.67 | R20: =VLOOKUP($F20,[1]装箱单!$A:$F,6,0) -> 18.78 | S20: =VLOOKUP($F20,[1]装箱单!$A:$G,7,0) -> 32.385 | T20: =VLOOKUP($F20,[1]装箱单!$A:$J,10,0) -> 0.016220435 | U20: =+T20*L20 -> 18.199328
A21: 46029 | B21: WMUS | C21: POHK-25-18803 | E21: 953742276 | F21: 11369（1） | G21: 成品 | I21: 924 | J21: 个 | K21: 装配 | L21: 924 | M21: =+U21 -> 14.987682 | N21: 未 | Q21: =VLOOKUP($F21,[1]装箱单!$A:$E,5,0) -> 26.67 | R21: =VLOOKUP($F21,[1]装箱单!$A:$F,6,0) -> 18.78 | S21: =VLOOKUP($F21,[1]装箱单!$A:$G,7,0) -> 32.385 | T21: =VLOOKUP($F21,[1]装箱单!$A:$J,10,0) -> 0.016220435 | U21: =+T21*L21 -> 14.987682
A22: 46029 | B22: WMUS | C22: POHK-25-18805 | E22: 953742289 | F22: 11369（1） | G22: 成品 | I22: 1056 | J22: 个 | K22: 装配 | L22: =1056-66 -> 990 | M22: =+U22 -> 16.058231 | N22: 未 | Q22: =VLOOKUP($F22,[1]装箱单!$A:$E,5,0) -> 26.67 | R22: =VLOOKUP($F22,[1]装箱单!$A:$F,6,0) -> 18.78 | S22: =VLOOKUP($F22,[1]装箱单!$A:$G,7,0) -> 32.385 | T22: =VLOOKUP($F22,[1]装箱单!$A:$J,10,0) -> 0.016220435 | U22: =+T22*L22 -> 16.058231
A23: 46029 | B23: Domestic | C23: 43721 | F23: 320635 | G23: 成品 | I23: =+L23*2 -> 404 | J23: 个 | K23: 装配 | L23: 202 | M23: =+U23 -> 3.1889208 | N23: 未 | Q23: =VLOOKUP($F23,[1]装箱单!$A:$E,5,0) -> 35.18 | R23: =VLOOKUP($F23,[1]装箱单!$A:$F,6,0) -> 27.18 | S23: =VLOOKUP($F23,[1]装箱单!$A:$G,7,0) -> 16.51 | T23: =VLOOKUP($F23,[1]装箱单!$A:$J,10,0) -> 0.015786737 | U23: =+T23*L23 -> 3.1889208
A24: 46029 | B24: Domestic | C24: 43649 | F24: 470616（4） | G24: 成品 | I24: =+L24*4 -> 6000 | J24: 个 | K24: 装配 | L24: 1500 | M24: =+U24 -> 23.8392 | N24: 未 | O24: 必走 | Q24: =VLOOKUP($F24,[1]装箱单!$A:$E,5,0) -> 33 | R24: =VLOOKUP($F24,[1]装箱单!$A:$F,6,0) -> 17.2 | S24: =VLOOKUP($F24,[1]装箱单!$A:$G,7,0) -> 28 | T24: =VLOOKUP($F24,[1]装箱单!$A:$J,10,0) -> 0.0158928 | U24: =+T24*L24 -> 23.8392
A25: 46029 | B25: Domestic | C25: 43721 | F25: 470111（4） | G25: 成品 | I25: =+L25*4 -> 6000 | J25: 个 | K25: 装配 | L25: 1500 | M25: =+U25 -> 22.833825 | N25: 未 | O25: 必走 | Q25: =VLOOKUP($F25,[1]装箱单!$A:$E,5,0) -> 27.94 | R25: =VLOOKUP($F25,[1]装箱单!$A:$F,6,0) -> 16.51 | S25: =VLOOKUP($F25,[1]装箱单!$A:$G,7,0) -> 33 | T25: =VLOOKUP($F25,[1]装箱单!$A:$J,10,0) -> 0.01522255 | U25: =+T25*L25 -> 22.833825
M26: =SUM(M20:M25) -> 99.107188
A27: 46030 | B27: WMUS | C27: 从AMZ询单取消2468个转入 POHK-25-18804 | E27: 953742278 | F27: 11369（1） | G27: 成品 | I27: 858 | J27: 个 | K27: 装配 | L27: 858 | M27: =+U27 -> 13.917133 | N27: 已 | P27: 车牌:川SB1976 司机：蔡旭 电话：15881855371 | Q27: =VLOOKUP($F27,[1]装箱单!$A:$E,5,0) -> 26.67 | R27: =VLOOKUP($F27,[1]装箱单!$A:$F,6,0) -> 18.78 | S27: =VLOOKUP($F27,[1]装箱单!$A:$G,7,0) -> 32.385 | T27: =VLOOKUP($F27,[1]装箱单!$A:$J,10,0) -> 0.016220435 | U27: =+T27*L27 -> 13.917133
A28: 46030 | B28: WMUS | C28: POHK-25-18805 | E28: 953742289 | F28: 11369（1） | G28: 成品 | I28: 1056 | J28: 个 | K28: 装配 | L28: 66 | M28: =+U28 -> 1.0705487 | N28: 已 | Q28: =VLOOKUP($F28,[1]装箱单!$A:$E,5,0) -> 26.67 | R28: =VLOOKUP($F28,[1]装箱单!$A:$F,6,0) -> 18.78 | S28: =VLOOKUP($F28,[1]装箱单!$A:$G,7,0) -> 32.385 | T28: =VLOOKUP($F28,[1]装箱单!$A:$J,10,0) -> 0.016220435 | U28: =+T28*L28 -> 1.0705487
A29: 46030 | B29: WMUS | C29: POHK-25-18806 | E29: 953742290 | F29: 11369（1） | G29: 成品 | I29: 1584 | J29: 个 | K29: 装配 | L29: 1584 | M29: =+U29 -> 25.69317 | N29: 已 | Q29: =VLOOKUP($F29,[1]装箱单!$A:$E,5,0) -> 26.67 | R29: =VLOOKUP($F29,[1]装箱单!$A:$F,6,0) -> 18.78 | S29: =VLOOKUP($F29,[1]装箱单!$A:$G,7,0) -> 32.385 | T29: =VLOOKUP($F29,[1]装箱单!$A:$J,10,0) -> 0.016220435 | U29: =+T29*L29 -> 25.69317
A30: 46030 | B30: WMUS | C30: POHK-25-18807 | E30: 953742291 | F30: 11369（1） | G30: 成品 | I30: 1254 | J30: 个 | K30: 装配 | L30: 1254 | M30: =+U30 -> 20.340426 | N30: 已 | Q30: =VLOOKUP($F30,[1]装箱单!$A:$E,5,0) -> 26.67 | R30: =VLOOKUP($F30,[1]装箱单!$A:$F,6,0) -> 18.78 | S30: =VLOOKUP($F30,[1]装箱单!$A:$G,7,0) -> 32.385 | T30: =VLOOKUP($F30,[1]装箱单!$A:$J,10,0) -> 0.016220435 | U30: =+T30*L30 -> 20.340426
A31: 46030 | B31: WMUS | C31: POHK-25-18808 | E31: 953742296 | F31: 11369（1） | G31: 成品 | I31: 924 | J31: 个 | K31: 装配 | L31: 924 | M31: =+U31 -> 14.987682 | N31: 已 | Q31: =VLOOKUP($F31,[1]装箱单!$A:$E,5,0) -> 26.67 | R31: =VLOOKUP($F31,[1]装箱单!$A:$F,6,0) -> 18.78 | S31: =VLOOKUP($F31,[1]装箱单!$A:$G,7,0) -> 32.385 | T31: =VLOOKUP($F31,[1]装箱单!$A:$J,10,0) -> 0.016220435 | U31: =+T31*L31 -> 14.987682
A32: 46030 | B32: WMUS | C32: 43670 | E32: "0953760398 | F32: 570989 | G32: 成品 | I32: =+L32*27 -> 6696 | J32: 个 | K32: 装配 | L32: 248 | M32: =+U32 -> 2.7672695 | N32: 已 | Q32: =VLOOKUP($F32,[1]装箱单!$A:$E,5,0) -> 31.115 | R32: =VLOOKUP($F32,[1]装箱单!$A:$F,6,0) -> 22.59 | S32: =VLOOKUP($F32,[1]装箱单!$A:$G,7,0) -> 15.875 | T32: =VLOOKUP($F32,[1]装箱单!$A:$J,10,0) -> 0.011158345 | U32: =+T32*L32 -> 2.7672695
A33: 46030 | B33: WMUS | C33: 43674 | E33: "0953760449 | F33: 570989 | G33: 成品 | I33: =+L33*27 -> 5994 | J33: 个 | K33: 装配 | L33: 222 | M33: =+U33 -> 2.4771525 | N33: 已 | Q33: =VLOOKUP($F33,[1]装箱单!$A:$E,5,0) -> 31.115 | R33: =VLOOKUP($F33,[1]装箱单!$A:$F,6,0) -> 22.59 | S33: =VLOOKUP($F33,[1]装箱单!$A:$G,7,0) -> 15.875 | T33: =VLOOKUP($F33,[1]装箱单!$A:$J,10,0) -> 0.011158345 | U33: =+T33*L33 -> 2.4771525
A34: 46030 | B34: WMUS | C34: 43683 | E34: "0953763886 | F34: 570989 | G34: 成品 | I34: =+L34*27 -> 216 | J34: 个 | K34: 装配 | L34: 8 | M34: =+U34 -> 0.089266757 | N34: 已 | Q34: =VLOOKUP($F34,[1]装箱单!$A:$E,5,0) -> 31.115 | R34: =VLOOKUP($F34,[1]装箱单!$A:$F,6,0) -> 22.59 | S34: =VLOOKUP($F34,[1]装箱单!$A:$G,7,0) -> 15.875 | T34: =VLOOKUP($F34,[1]装箱单!$A:$J,10,0) -> 0.011158345 | U34: =+T34*L34 -> 0.089266757
A35: 46030 | B35: WMUS | C35: 43686 | E35: "0953763889 | F35: 570989 | G35: 成品 | I35: =+L35*27 -> 1296 | J35: 个 | K35: 装配 | L35: 48 | M35: =+U35 -> 0.53560054 | N35: 已 | Q35: =VLOOKUP($F35,[1]装箱单!$A:$E,5,0) -> 31.115 | R35: =VLOOKUP($F35,[1]装箱单!$A:$F,6,0) -> 22.59 | S35: =VLOOKUP($F35,[1]装箱单!$A:$G,7,0) -> 15.875 | T35: =VLOOKUP($F35,[1]装箱单!$A:$J,10,0) -> 0.011158345 | U35: =+T35*L35 -> 0.53560054
A36: 46030 | B36: WMUS | C36: 43690 | E36: "0953763893 | F36: 570989 | G36: 成品 | I36: =+L36*27 -> 4050 | J36: 个 | K36: 装配 | L36: 150 | M36: =+U36 -> 1.6737517 | N36: 已 | Q36: =VLOOKUP($F36,[1]装箱单!$A:$E,5,0) -> 31.115 | R36: =VLOOKUP($F36,[1]装箱单!$A:$F,6,0) -> 22.59 | S36: =VLOOKUP($F36,[1]装箱单!$A:$G,7,0) -> 15.875 | T36: =VLOOKUP($F36,[1]装箱单!$A:$J,10,0) -> 0.011158345 | U36: =+T36*L36 -> 1.6737517
A37: 46030 | B37: WMUS | C37: 43691 | E37: "0953763894 | F37: 570989 | G37: 成品 | I37: =+L37*27 -> 648 | J37: 个 | K37: 装配 | L37: 24 | M37: =+U37 -> 0.26780027 | N37: 已 | Q37: =VLOOKUP($F37,[1]装箱单!$A:$E,5,0) -> 31.115 | R37: =VLOOKUP($F37,[1]装箱单!$A:$F,6,0) -> 22.59 | S37: =VLOOKUP($F37,[1]装箱单!$A:$G,7,0) -> 15.875 | T37: =VLOOKUP($F37,[1]装箱单!$A:$J,10,0) -> 0.011158345 | U37: =+T37*L37 -> 0.26780027
A38: 46030 | B38: WMUS | C38: 43688 | E38: "0953763891 | F38: 570989 | G38: 成品 | I38: =+L38*27 -> 2160 | J38: 个 | K38: 装配 | L38: 80 | M38: =+U38 -> 0.89266757 | N38: 已 | Q38: =VLOOKUP($F38,[1]装箱单!$A:$E,5,0) -> 31.115 | R38: =VLOOKUP($F38,[1]装箱单!$A:$F,6,0) -> 22.59 | S38: =VLOOKUP($F38,[1]装箱单!$A:$G,7,0) -> 15.875 | T38: =VLOOKUP($F38,[1]装箱单!$A:$J,10,0) -> 0.011158345 | U38: =+T38*L38 -> 0.89266757
A39: 46030 | B39: WMUS | C39: 43694 | E39: "0953763897 | F39: 570989 | G39: 成品 | I39: =+L39*27 -> 2160 | J39: 个 | K39: 装配 | L39: 80 | M39: =+U39 -> 0.89266757 | N39: 已 | O39: 必走 | Q39: =VLOOKUP($F39,[1]装箱单!$A:$E,5,0) -> 31.115 | R39: =VLOOKUP($F39,[1]装箱单!$A:$F,6,0) -> 22.59 | S39: =VLOOKUP($F39,[1]装箱单!$A:$G,7,0) -> 15.875 | T39: =VLOOKUP($F39,[1]装箱单!$A:$J,10,0) -> 0.011158345 | U39: =+T39*L39 -> 0.89266757
A40: 46030 | B40: Disney Theme Park | C40: POHK-25-20703 | E40: W-9433791 | F40: 14265（18） | G40: 成品 | I40: =+L40*18 -> 5994 | J40: 个 | K40: 装配 | L40: 333 | M40: =+U40 -> 4.9991399 | N40: 已 | O40: 必走 | Q40: =VLOOKUP($F40,[1]装箱单!$A:$E,5,0) -> 42.48 | R40: =VLOOKUP($F40,[1]装箱单!$A:$F,6,0) -> 22.8 | S40: =VLOOKUP($F40,[1]装箱单!$A:$G,7,0) -> 15.5 | T40: =VLOOKUP($F40,[1]装箱单!$A:$J,10,0) -> 0.015012432 | U40: =+T40*L40 -> 4.9991399
...

Sheet 2026年6月
A1: 成品当日发货清单
A2: 工厂地址：四川省达州市渠县经济开发区 | G2: 制单人：代艳 | I2: 联系电话1368664967 | K2: 备注：装车时按从上下到的顺序装车 | Q2: CARTON DIMENSIONS | T2: CRTN CBM (M3) | U2: TOTAL CBM (M3)
A3: 发车日期 | B3: 客户 | C3: 生产单号 | D3: 销售单号 | E3: PO.NO | F3: 款号 | G3: 产品名称 | H3: 总箱数 | I3: 实发数量 | J3: 单位 | K3: 产地 | L3: 件数 | M3: CBM | N3: 是否验货 | O3: 备注 | P3: 运输方式 | Q3: L (cm) | R3: W (cm) | S3: H (cm)
A4: 46175 | B4: SMYTHS UK | C4: POHK-26-02582 | D4: XSDD000201 | E4: 4400545904 | F4: 46496 | G4: =VLOOKUP(F4,[1]装箱单!$A:$C,3,0) -> 米妮系列 | H4: 1232 | I4: =+L4*2 -> 2464 | J4: 套 | K4: 装配 | L4: 1232 | M4: =+U4 -> 27.554565 | N4: 已 | P4: 车牌：川S80435 挂号：川S4486 司机：秦学川 电话：15808181018 | Q4: =VLOOKUP($F4,[1]装箱单!$A:$E,5,0) -> 40.01 | R4: =VLOOKUP($F4,[1]装箱单!$A:$F,6,0) -> 26.67 | S4: =VLOOKUP($F4,[1]装箱单!$A:$G,7,0) -> 20.96 | T4: =VLOOKUP($F4,[1]装箱单!$A:$J,10,0) -> 0.022365718 | U4: =+T4*L4 -> 27.554565
A5: 46175 | B5: B&M UK | C5: POHK-26-03482 | D5: XSDD000254 | E5: 02460228/1 | F5: 46132 | G5: =VLOOKUP(F5,[1]装箱单!$A:$C,3,0) -> 赛车总动员系列 | H5: 1737 | I5: =+L5*2 -> 3474 | J5: 套 | K5: 装配 | L5: 1737 | M5: =+U5 -> 38.849252 | N5: 已 | Q5: =VLOOKUP($F5,[1]装箱单!$A:$E,5,0) -> 40.01 | R5: =VLOOKUP($F5,[1]装箱单!$A:$F,6,0) -> 26.67 | S5: =VLOOKUP($F5,[1]装箱单!$A:$G,7,0) -> 20.96 | T5: =VLOOKUP($F5,[1]装箱单!$A:$J,10,0) -> 0.022365718 | U5: =+T5*L5 -> 38.849252
A6: 46175 | B6: B&M UK | C6: POHK-26-03484 | D6: XSDD000254 | E6: 02460286/1 | F6: 46132 | G6: =VLOOKUP(F6,[1]装箱单!$A:$C,3,0) -> 赛车总动员系列 | H6: 1737 | I6: =+L6*2 -> 3474 | J6: 套 | K6: 装配 | L6: 1737 | M6: =+U6 -> 38.849252 | N6: 已 | Q6: =VLOOKUP($F6,[1]装箱单!$A:$E,5,0) -> 40.01 | R6: =VLOOKUP($F6,[1]装箱单!$A:$F,6,0) -> 26.67 | S6: =VLOOKUP($F6,[1]装箱单!$A:$G,7,0) -> 20.96 | T6: =VLOOKUP($F6,[1]装箱单!$A:$J,10,0) -> 0.022365718 | U6: =+T6*L6 -> 38.849252
A7: 46175 | B7: Disney Theme Park | C7: POHK-26-10052 | D7: XSDD000470 | E7: L-9684413 | F7: 33708（8） | G7: =VLOOKUP(F7,[1]装箱单!$A:$C,3,0) -> 搪胶小鸭 | H7: 375 | I7: 3000 | J7: 个 | K7: 装配 | L7: 375 | M7: =+U7 -> 2.9552737 | N7: 已 | Q7: =VLOOKUP($F7,[1]装箱单!$A:$E,5,0) -> 33 | R7: =VLOOKUP($F7,[1]装箱单!$A:$F,6,0) -> 16.7 | S7: =VLOOKUP($F7,[1]装箱单!$A:$G,7,0) -> 14.3 | T7: =VLOOKUP($F7,[1]装箱单!$A:$J,10,0) -> 0.00788073 | U7: =+T7*L7 -> 2.9552737
A8: 46175 | B8: Disney Theme Park | C8: POHK-26-02815 | D8: XSDD000140 | E8: L-9666976 | F8: 33475（18） | G8: =VLOOKUP(F8,[1]装箱单!$A:$C,3,0) -> 鸭子 | H8: 7028 | I8: =+L8*18 -> 74970 | J8: 个 | K8: 装配 | L8: =7028-2863 -> 4165 | M8: =+U8 -> 24.127898 | N8: 已 | Q8: =VLOOKUP($F8,[1]装箱单!$A:$E,5,0) -> 32.385 | R8: =VLOOKUP($F8,[1]装箱单!$A:$F,6,0) -> 18.78 | S8: =VLOOKUP($F8,[1]装箱单!$A:$G,7,0) -> 9.525 | T8: =VLOOKUP($F8,[1]装箱单!$A:$J,10,0) -> 0.0057930126 | U8: =+T8*L8 -> 24.127898
M9: =SUM(M4:M8) -> 132.33624
A10: 46178 | B10: Amazon US | C10: POHK-26-09083 | D10: XSDD000335 | E10: 001-R0-AMZCA | F10: 12369（3） | G10: =VLOOKUP(F10,[1]装箱单!$A:$C,3,0) -> 摇摆米奇 | H10: 100 | I10: =+L10*3 -> 300 | J10: 个 | K10: 装配 | L10: 100 | M10: =+U10 -> 7.5620155 | N10: 已 | P10: 车牌：川S80435 挂号：川S4486 司机：秦学川 电话：15808181018 | Q10: =VLOOKUP($F10,[1]装箱单!$A:$E,5,0) -> 48.26 | R10: =VLOOKUP($F10,[1]装箱单!$A:$F,6,0) -> 36.83 | S10: =VLOOKUP($F10,[1]装箱单!$A:$G,7,0) -> 42.545 | T10: =VLOOKUP($F10,[1]装箱单!$A:$J,10,0) -> 0.075620155 | U10: =+T10*L10 -> 7.5620155
A11: 46178 | B11: The Warehouse | C11: POHK-26-01987 | D11: XSDD000154 | E11: 29556931 | F11: 28458 | G11: =VLOOKUP(F11,[1]装箱单!$A:$C,3,0) -> 五款硅胶手感球 | H11: 600 | I11: =+L11*3 -> 600 | J11: 套 | K11: 装配 | L11: 200 | M11: =+U11 -> 4.1660717 | N11: 已 | Q11: =VLOOKUP($F11,[1]装箱单!$A:$E,5,0) -> 26.99 | R11: =VLOOKUP($F11,[1]装箱单!$A:$F,6,0) -> 27.31 | S11: =VLOOKUP($F11,[1]装箱单!$A:$G,7,0) -> 28.26 | T11: =VLOOKUP($F11,[1]装箱单!$A:$J,10,0) -> 0.020830358 | U11: =+T11*L11 -> 4.1660717
A12: 46178 | B12: The Warehouse | C12: POHK-26-01987 | D12: XSDD000154 | E12: 29556931 | F12: 28472 | G12: =VLOOKUP(F12,[1]装箱单!$A:$C,3,0) -> 狮子 | H12: 600 | I12: 600 | J12: 个 | K12: 装配 | L12: 600 | M12: =+U12 -> 11.016 | N12: 已 | Q12: =VLOOKUP($F12,[1]装箱单!$A:$E,5,0) -> 30 | R12: =VLOOKUP($F12,[1]装箱单!$A:$F,6,0) -> 17 | S12: =VLOOKUP($F12,[1]装箱单!$A:$G,7,0) -> 36 | T12: =VLOOKUP($F12,[1]装箱单!$A:$J,10,0) -> 0.01836 | U12: =+T12*L12 -> 11.016
A13: 46178 | B13: The Warehouse | C13: POHK-26-01987 | D13: XSDD000154 | E13: 29556931 | F13: 28483 | G13: =VLOOKUP(F13,[1]装箱单!$A:$C,3,0) -> 振动球 | H13: 600 | I13: 600 | J13: 个 | K13: 装配 | L13: 600 | M13: =+U13 -> 3.463614 | N13: 已 | Q13: =VLOOKUP($F13,[1]装箱单!$A:$E,5,0) -> 16.83 | R13: =VLOOKUP($F13,[1]装箱单!$A:$F,6,0) -> 17.15 | S13: =VLOOKUP($F13,[1]装箱单!$A:$G,7,0) -> 20 | T13: =VLOOKUP($F13,[1]装箱单!$A:$J,10,0) -> 0.00577269 | U13: =+T13*L13 -> 3.463614
A14: 46178 | B14: Kohls （送华康） | C14: POHK-26-04355 | D14: XSDD000280 | E14: 984878580 | F14: 46857 | G14: =VLOOKUP(F14,[1]装箱单!$A:$C,3,0) -> 33477外星史迪仔 | H14: 70*66+30 | I14: 550 | J14: 个 | K14: 装配 | L14: 67 | N14: 已 | O14: 4650
A15: 46178 | B15: Kohls （送华康） | C15: POHK-26-04353 | D15: XSDD000278 | E15: 984878461 | F15: 46857 | G15: =VLOOKUP(F15,[1]装箱单!$A:$C,3,0) -> 33477外星史迪仔 | I15: 770 | J15: 个 | K15: 装配 | N15: 已
A16: 46178 | B16: Kohls （送华康） | C16: POHK-26-04354 | D16: XSDD000279 | E16: 984878548 | F16: 46857 | G16: =VLOOKUP(F16,[1]装箱单!$A:$C,3,0) -> 33477外星史迪仔 | I16: 550 | J16: 个 | K16: 装配 | N16: 已
A17: 46178 | B17: Kohls （送华康） | C17: POHK-26-04364 | D17: XSDD000291 | E17: 984878611 | F17: 46857 | G17: =VLOOKUP(F17,[1]装箱单!$A:$C,3,0) -> 33477外星史迪仔 | I17: =550-26 -> 524 | J17: 个 | K17: 装配 | M17: 1 | N17: 已
A18: 46178 | B18: Kohls （送华康） | C18: POHK-26-05228 | D18: XSDD000556 | E18: PO013819 | F18: 46886 | G18: =VLOOKUP(F18,[1]装箱单!$A:$C,3,0) -> 33477外星史迪仔 | I18: 1000 | J18: 个 | K18: 装配 | N18: 已
A19: 46178 | B19: Kohls （送华康） | C19: POHK-26-09115 | D19: XSDD000557 | E19: PO014156 | F19: 46886 | G19: =VLOOKUP(F19,[1]装箱单!$A:$C,3,0) -> 33477外星史迪仔 | I19: 300 | J19: 个 | K19: 装配 | N19: 已
A20: 46178 | B20: Kohls （送华康） | C20: POHK-26-08084 | D20: XSDD000411 | E20: 2000009967 | F20: 46886 | G20: =VLOOKUP(F20,[1]装箱单!$A:$C,3,0) -> 33477外星史迪仔 | I20: =1136-180 -> 956 | J20: 个 | K20: 装配 | N20: 已
A21: 46178 | B21: Kohls （送华康） | C21: POHK-26-04355 | D21: XSDD000280 | E21: 984878580 | F21: 46897 | G21: =VLOOKUP(F21,[1]装箱单!$A:$C,3,0) -> 33476天使 | H21: 80*36+20 | I21: 300 | J21: 个 | K21: 装配 | L21: 37 | N21: 已 | O21: 2900
A22: 46178 | B22: Kohls （送华康） | C22: POHK-26-04353 | D22: XSDD000278 | E22: 984878461 | F22: 46897 | G22: =VLOOKUP(F22,[1]装箱单!$A:$C,3,0) -> 33476天使 | I22: 400 | J22: 个 | K22: 装配 | N22: 已
A23: 46178 | B23: Kohls （送华康） | C23: POHK-26-04354 | D23: XSDD000279 | E23: 984878548 | F23: 46897 | G23: =VLOOKUP(F23,[1]装箱单!$A:$C,3,0) -> 33476天使 | I23: 300 | J23: 个 | K23: 装配 | N23: 已
A24: 46178 | B24: Kohls （送华康） | C24: POHK-26-04363 | D24: XSDD000290 | E24: 984878589 | F24: 46897 | G24: =VLOOKUP(F24,[1]装箱单!$A:$C,3,0) -> 33476天使 | I24: 300 | J24: 个 | K24: 装配 | N24: 已
A25: 46178 | B25: Kohls （送华康） | C25: POHK-26-04364 | D25: XSDD000291 | E25: 984878611 | F25: 46897 | G25: =VLOOKUP(F25,[1]装箱单!$A:$C,3,0) -> 33476天使 | I25: 300 | J25: 个 | K25: 装配 | N25: 已
A26: 46178 | B26: Kohls （送华康） | C26: POHK-26-04361 | D26: XSDD000288 | E26: 984878332 | F26: 46897 | G26: =VLOOKUP(F26,[1]装箱单!$A:$C,3,0) -> 33476天使 | I26: 200 | J26: 个 | K26: 装配 | N26: 已
A27: 46178 | B27: Kohls （送华康） | C27: POHK-26-04362 | D27: XSDD000289 | E27: 984878334 | F27: 46897 | G27: =VLOOKUP(F27,[1]装箱单!$A:$C,3,0) -> 33476天使 | I27: 200 | J27: 个 | K27: 装配 | N27: 已
A28: 46178 | B28: Kohls （送华康） | C28: POHK-26-05228 | D28: XSDD000556 | E28: PO013819 | F28: 46913-1 | G28: =VLOOKUP(F28,[1]装箱单!$A:$C,3,0) -> 33476天使 | I28: 900 | J28: 个 | K28: 装配 | N28: 已
A29: 46178 | B29: Kohls （送华康） | C29: POHK-26-05228 | D29: XSDD000556 | E29: PO013819 | F29: 46913-2 | G29: =VLOOKUP(F29,[1]装箱单!$A:$C,3,0) -> 33416史迪仔 | H29: 200+640+60 | I29: 900 | J29: 个 | K29: 装配 | L29: 10 | N29: 已 | O29: 900
A30: 46178 | B30: Kohls （送华康） | C30: POHK-26-06248 | D30: XSDD000325 | E30: 117403871 | F30: 46862 | G30: =VLOOKUP(F30,[1]装箱单!$A:$C,3,0) -> 荧光杰克 | H30: 80*90+200+320+153 | I30: 2640 | J30: 个 | K30: 装配 | L30: 96 | N30: 已 | O30: 7773
A31: 46178 | B31: Kohls （送华康） | C31: POHK-26-06249 | D31: XSDD000536 | E31: 117405873 | F31: 46862 | G31: =VLOOKUP(F31,[1]装箱单!$A:$C,3,0) -> 荧光杰克 | I31: 2640 | J31: 个 | K31: 装配 | N31: 已
A32: 46178 | B32: Kohls （送华康） | C32: POHK-26-09963 | D32: XSDD000510 | E32: 6870-R0-AMZ | F32: 46862 | G32: =VLOOKUP(F32,[1]装箱单!$A:$C,3,0) -> 荧光杰克 | I32: 840 | J32: 个 | K32: 装配 | M32: 1 | N32: 已
A33: 46178 | B33: Kohls （送华康） | C33: POHK-26-05034 | D33: XSDD000399 | E33: 7000995354 | F33: 46862 | G33: =VLOOKUP(F33,[1]装箱单!$A:$C,3,0) -> 荧光杰克 | I33: 500 | J33: 个 | K33: 装配 | N33: 已
A34: 46178 | B34: Kohls （送华康） | C34: POHK-26-05036 | D34: XSDD000551 | E34: 7000995356 | F34: 46862 | G34: =VLOOKUP(F34,[1]装箱单!$A:$C,3,0) -> 荧光杰克 | I34: 500 | J34: 个 | K34: 装配 | N34: 已
A35: 46178 | B35: Kohls （送华康） | C35: POHK-26-05037 | D35: XSDD000552 | E35: 7000995357 | F35: 46862 | G35: =VLOOKUP(F35,[1]装箱单!$A:$C,3,0) -> 荧光杰克 | I35: 653 | J35: 个 | K35: 装配 | N35: 已
A36: 46178 | B36: The Warehouse | C36: POHK-26-01987 | D36: XSDD000154 | E36: 29556931 | F36: 28481 | G36: =VLOOKUP(F36,[1]装箱单!$A:$C,3,0) -> 骰子 | H36: =+I36/4 -> 150 | I36: =+L36*4 -> 600 | J36: 套 | K36: 装配 | L36: 150 | M36: =+U36 -> 1.5119652 | N36: 已 | Q36: =VLOOKUP($F36,[1]装箱单!$A:$E,5,0) -> 23.81 | R36: =VLOOKUP($F36,[1]装箱单!$A:$F,6,0) -> 17.78 | S36: =VLOOKUP($F36,[1]装箱单!$A:$G,7,0) -> 23.81 | T36: =VLOOKUP($F36,[1]装箱单!$A:$J,10,0) -> 0.010079768 | U36: =+T36*L36 -> 1.5119652
A37: 46178 | B37: TJX (POE) | C37: POHK-26-11743 | D37: XSDD000517 | E37: 137054 | F37: 33454(48) | G37: =VLOOKUP(F37,[1]装箱单!$A:$C,3,0) -> 鸭子 | H37: 288 | I37: 13824 | J37: 个 | K37: 装配 | L37: 288 | M37: =+U37 -> 11.771474 | N37: 已 | Q37: =VLOOKUP($F37,[1]装箱单!$A:$E,5,0) -> 37.15 | R37: =VLOOKUP($F37,[1]装箱单!$A:$F,6,0) -> 33 | S37: =VLOOKUP($F37,[1]装箱单!$A:$G,7,0) -> 33.34 | T37: =VLOOKUP($F37,[1]装箱单!$A:$J,10,0) -> 0.040873173 | U37: =+T37*L37 -> 11.771474
A38: 46178 | B38: TJX (POE) | C38: POHK-26-11786 | D38: XSDD000516 | E38: 137058 | F38: 33454(48) | G38: =VLOOKUP(F38,[1]装箱单!$A:$C,3,0) -> 鸭子 | H38: 312 | I38: 14976 | J38: 个 | K38: 装配 | L38: 312 | M38: =+U38 -> 12.75243 | N38: 已 | Q38: =VLOOKUP($F38,[1]装箱单!$A:$E,5,0) -> 37.15 | R38: =VLOOKUP($F38,[1]装箱单!$A:$F,6,0) -> 33 | S38: =VLOOKUP($F38,[1]装箱单!$A:$G,7,0) -> 33.34 | T38: =VLOOKUP($F38,[1]装箱单!$A:$J,10,0) -> 0.040873173 | U38: =+T38*L38 -> 12.75243
A39: 46178 | B39: Auchan France | C39: POHK-26-06752 | D39: XSDD000420 | E39: 875099 | F39: 46134 | G39: =VLOOKUP(F39,[1]装箱单!$A:$C,3,0) -> 海洋奇缘系列 | H39: =+I39/2 -> 473 | I39: =+L39*2 -> 946 | J39: 套 | K39: 装配 | L39: 473 | M39: =+U39 -> 10.578985 | N39: 已 | Q39: =VLOOKUP($F39,[1]装箱单!$A:$E,5,0) -> 40.01 | R39: =VLOOKUP($F39,[1]装箱单!$A:$F,6,0) -> 26.67 | S39: =VLOOKUP($F39,[1]装箱单!$A:$G,7,0) -> 20.96 | T39: =VLOOKUP($F39,[1]装箱单!$A:$J,10,0) -> 0.022365718 | U39: =+T39*L39 -> 10.578985
A40: 46178 | B40: Auchan France | C40: POHK-26-06753 | D40: XSDD000421 | E40: 875100 | F40: 46134 | G40: =VLOOKUP(F40,[1]装箱单!$A:$C,3,0) -> 海洋奇缘系列 | H40: =+I40/2 -> 533 | I40: =+L40*2 -> 1066 | J40: 套 | K40: 装配 | L40: 533 | M40: =+U40 -> 11.920928 | N40: 已 | Q40: =VLOOKUP($F40,[1]装箱单!$A:$E,5,0) -> 40.01 | R40: =VLOOKUP($F40,[1]装箱单!$A:$F,6,0) -> 26.67 | S40: =VLOOKUP($F40,[1]装箱单!$A:$G,7,0) -> 20.96 | T40: =VLOOKUP($F40,[1]装箱单!$A:$J,10,0) -> 0.022365718 | U40: =+T40*L40 -> 11.920928
...

Sheet Sheet2

Sheet Sheet3
